Workbook

Sheet Dashboard
A1: CPI Case Study
A17: INSIGHT 1 : Food and Beverages contributes the highest in CPI calculation in the latest month across all the sectors.
A34: INSIGHT 2:
A35: 2022 is the year with highest inflation rate.
A36: Prices of Cereals and products , Spices and Fuel and light increased in year 2022 which is the reason of high inflation rate in the year 2022.
A54: INSIGHT 3:
A55: June month has the highest inflation rate whereas in december inflation rate is lowest.
A56: Cereals and products & Spices are the individual category that contributes the highest in rising inflation rate.
A74: INSIGHT 4:
A75: Health inflation shows a sustained,elevated rise across all the sectors post-covid which signifies increase in medical service cost.
A76: Food and Beverages category experienced a sharp spike in inflation across all the sectors post -covid due to demand and supply.
A77: Essential services shows a high upward trend across all the sectors post - covid influenced by high global fuel prices and transport services.
A97: INSIGHT 5: A strong positive correlation is observed between crude oil and (Meat and fish,Oils and fats,Transport and communication).

Sheet CPI data
A1: Sector | B1: Year | C1: Month | D1: Month number | E1: Cereals and products | F1: Meat and fish | G1: Egg | H1: Milk and products | I1: Oils and fats | J1: Fruits | K1: Vegetables | L1: Pulses and products | M1: Sugar and Confectionery | N1: Spices | O1: Nonalcoholic beverages | P1: Prepared meals, scks, sweets etc. | Q1: Food and beverages | R1: Pan, tobacco and intoxicants | S1: Clothing | T1: Footwear | U1: Clothing and footwear | V1: Housing | W1: Fuel and light | X1: Household goods and services | Y1: Health | Z1: Persol care and effects | AA1: Education | AB1: Recreation and amusement | AC1: Transport and communication | AD1: Miscellaneous | AE1: General index
A2: Rural | B2: 2013 | C2: January | D2: =IF(C2="January",1, IF(C2="february",2, IF(C2="march",3, IF(C2="april",4, IF(C2="may",5, IF(C2="june",6, IF(C2="july",7, IF(C2="august",8, IF(C2="september",9, IF(C2="october",10, IF(C2="november",11, IF(C2="december",12, )))))))))))) -> 1 | E2: 107.5 | F2: 106.3 | G2: 108.1 | H2: 104.9 | I2: 106.1 | J2: 103.9 | K2: 101.9 | L2: 106.1 | M2: 106.8 | N2: 103.1 | O2: 104.8 | P2: 106.7 | Q2: 105.5 | R2: 105.1 | S2: 106.5 | T2: 105.8 | U2: 106.4 | V2: ='Missing values'!V7 -> 100.3 | W2: 105.5 | X2: 104.8 | Y2: 104 | Z2: 104.7 | AA2: 103.8 | AB2: 103.4 | AC2: 103.3 | AD2: 104 | AE2: 105.1
A3: Rural+Urban | B3: 2013 | C3: January | D3: =IF(C3="January",1, IF(C3="february",2, IF(C3="march",3, IF(C3="april",4, IF(C3="may",5, IF(C3="june",6, IF(C3="july",7, IF(C3="august",8, IF(C3="september",9, IF(C3="october",10, IF(C3="november",11, IF(C3="december",12, )))))))))))) -> 1 | E3: 108.4 | F3: 107.3 | G3: 110 | H3: 104.4 | I3: 105.1 | J3: 103.2 | K3: 102.2 | L3: 106 | M3: 106.2 | N3: 102.7 | O3: 104.9 | P3: 107.3 | Q3: 105.6 | R3: 105.1 | S3: 106.3 | T3: 105.5 | U3: 106.2 | V3: 100.3 | W3: 105.5 | X3: 104.8 | Y3: 104 | Z3: 104.5 | AA3: 103.6 | AB3: 103.1 | AC3: 103.2 | AD3: 103.9 | AE3: 104.6
A4: Urban | B4: 2013 | C4: January | D4: =IF(C4="January",1, IF(C4="february",2, IF(C4="march",3, IF(C4="april",4, IF(C4="may",5, IF(C4="june",6, IF(C4="july",7, IF(C4="august",8, IF(C4="september",9, IF(C4="october",10, IF(C4="november",11, IF(C4="december",12, )))))))))))) -> 1 | E4: 110.5 | F4: 109.1 | G4: 113 | H4: 103.6 | I4: 103.4 | J4: 102.3 | K4: 102.9 | L4: 105.8 | M4: 105.1 | N4: 101.8 | O4: 105.1 | P4: 107.9 | Q4: 105.9 | R4: 105.2 | S4: 105.9 | T4: 105 | U4: 105.8 | V4: 100.3 | W4: 105.4 | X4: 104.8 | Y4: 104.1 | Z4: 104.3 | AA4: 103.5 | AB4: 102.9 | AC4: 103.2 | AD4: 103.7 | AE4: 104
A5: Rural | B5: 2013 | C5: February | D5: =IF(C5="January",1, IF(C5="february",2, IF(C5="march",3, IF(C5="april",4, IF(C5="may",5, IF(C5="june",6, IF(C5="july",7, IF(C5="august",8, IF(C5="september",9, IF(C5="october",10, IF(C5="november",11, IF(C5="december",12, )))))))))))) -> 2 | E5: 109.2 | F5: 108.7 | G5: 110.2 | H5: 105.4 | I5: 106.7 | J5: 104 | K5: 102.4 | L5: 105.9 | M5: 105.7 | N5: 103.1 | O5: 105.1 | P5: 107.7 | Q5: 106.3 | R5: 105.6 | S5: 107.1 | T5: 106.3 | U5: 107 | V5: ='Missing values'!V40 -> 100.4 | W5: 106.2 | X5: 105.2 | Y5: 104.4 | Z5: 104.6 | AA5: 104.1 | AB5: 104 | AC5: 103.9 | AD5: 104.4 | AE5: 105.8
A6: Rural+Urban | B6: 2013 | C6: February | D6: =IF(C6="January",1, IF(C6="february",2, IF(C6="march",3, IF(C6="april",4, IF(C6="may",5, IF(C6="june",6, IF(C6="july",7, IF(C6="august",8, IF(C6="september",9, IF(C6="october",10, IF(C6="november",11, IF(C6="december",12, )))))))))))) -> 2 | E6: 110.4 | F6: 110.2 | G6: 112.8 | H6: 104.9 | I6: 105.5 | J6: 103.6 | K6: 103.2 | L6: 105.3 | M6: 105.1 | N6: 102.8 | O6: 105.5 | P6: 108.3 | Q6: 106.6 | R6: 105.7 | S6: 106.9 | T6: 106 | U6: 106.8 | V6: 100.4 | W6: 106 | X6: 105.2 | Y6: 104.5 | Z6: 104.5 | AA6: 103.9 | AB6: 103.6 | AC6: 104.2 | AD6: 104.4 | AE6: 105.3
A7: Urban | B7: 2013 | C7: February | D7: =IF(C7="January",1, IF(C7="february",2, IF(C7="march",3, IF(C7="april",4, IF(C7="may",5, IF(C7="june",6, IF(C7="july",7, IF(C7="august",8, IF(C7="september",9, IF(C7="october",10, IF(C7="november",11, IF(C7="december",12, )))))))))))) -> 2 | E7: 112.9 | F7: 112.9 | G7: 116.9 | H7: 104 | I7: 103.5 | J7: 103.1 | K7: 104.9 | L7: 104.1 | M7: 103.8 | N7: 102.3 | O7: 106 | P7: 109 | Q7: 107.2 | R7: 106 | S7: 106.6 | T7: 105.5 | U7: 106.4 | V7: 100.4 | W7: 105.7 | X7: 105.2 | Y7: 104.7 | Z7: 104.3 | AA7: 103.7 | AB7: 103.3 | AC7: 104.4 | AD7: 104.3 | AE7: 104.7
A8: Rural | B8: 2013 | C8: March | D8: =IF(C8="January",1, IF(C8="february",2, IF(C8="march",3, IF(C8="april",4, IF(C8="may",5, IF(C8="june",6, IF(C8="july",7, IF(C8="august",8, IF(C8="september",9, IF(C8="october",10, IF(C8="november",11, IF(C8="december",12, )))))))))))) -> 3 | E8: 110.2 | F8: 108.8 | G8: 109.9 | H8: 105.6 | I8: 106.2 | J8: 105.7 | K8: 101.4 | L8: 105.7 | M8: 105 | N8: 103.3 | O8: 105.6 | P8: 108.2 | Q8: 106.6 | R8: 106.5 | S8: 107.6 | T8: 106.8 | U8: 107.5 | V8: ='Missing values'!V73 -> 100.4 | W8: 106.1 | X8: 105.6 | Y8: 104.7 | Z8: 104.3 | AA8: 104.3 | AB8: 104 | AC8: 104.6 | AD8: 104.6 | AE8: 106
A9: Rural+Urban | B9: 2013 | C9: March | D9: =IF(C9="January",1, IF(C9="february",2, IF(C9="march",3, IF(C9="april",4, IF(C9="may",5, IF(C9="june",6, IF(C9="july",7, IF(C9="august",8, IF(C9="september",9, IF(C9="october",10, IF(C9="november",11, IF(C9="december",12, )))))))))))) -> 3 | E9: 111.4 | F9: 109.7 | G9: 111.2 | H9: 105.1 | I9: 104.9 | J9: 105.3 | K9: 102.2 | L9: 105 | M9: 104.2 | N9: 103 | O9: 106.2 | P9: 108.9 | Q9: 106.9 | R9: 106.6 | S9: 107.4 | T9: 106.5 | U9: 107.3 | V9: 100.4 | W9: 106.1 | X9: 105.6 | Y9: 104.9 | Z9: 104.3 | AA9: 104 | AB9: 103.7 | AC9: 105.1 | AD9: 104.7 | AE9: 105.5
A10: Urban | B10: 2013 | C10: March | D10: =IF(C10="January",1, IF(C10="february",2, IF(C10="march",3, IF(C10="april",4, IF(C10="may",5, IF(C10="june",6, IF(C10="july",7, IF(C10="august",8, IF(C10="september",9, IF(C10="october",10, IF(C10="november",11, IF(C10="december",12, )))))))))))) -> 3 | E10: 113.9 | F10: 111.4 | G10: 113.2 | H10: 104.3 | I10: 102.7 | J10: 104.9 | K10: 103.8 | L10: 103.5 | M10: 102.6 | N10: 102.4 | O10: 107 | P10: 109.8 | Q10: 107.3 | R10: 106.8 | S10: 107.2 | T10: 106 | U10: 107 | V10: 100.4 | W10: 106 | X10: 105.7 | Y10: 105.2 | Z10: 104.2 | AA10: 103.8 | AB10: 103.5 | AC10: 105.5 | AD10: 104.9 | AE10: 105
A11: Rural | B11: 2013 | C11: April | D11: =IF(C11="January",1, IF(C11="february",2, IF(C11="march",3, IF(C11="april",4, IF(C11="may",5, IF(C11="june",6, IF(C11="july",7, IF(C11="august",8, IF(C11="september",9, IF(C11="october",10, IF(C11="november",11, IF(C11="december",12, )))))))))))) -> 4 | E11: 110.2 | F11: 109.5 | G11: 106.9 | H11: 106.3 | I11: 105.7 | J11: 108.3 | K11: 103.4 | L11: 105.7 | M11: 104.2 | N11: 103.2 | O11: 106.5 | P11: 108.8 | Q11: 107.1 | R11: 107.1 | S11: 108.1 | T11: 107.4 | U11: 108 | V11: ='Missing values'!V106 -> 100.5 | W11: 106.5 | X11: 106.1 | Y11: 105.1 | Z11: 102.7 | AA11: 104.8 | AB11: 104.5 | AC11: 104.4 | AD11: 104.6 | AE11: 106.4
A12: Rural+Urban | B12: 2013 | C12: April | D12: =IF(C12="January",1, IF(C12="february",2, IF(C12="march",3, IF(C12="april",4, IF(C12="may",5, IF(C12="june",6, IF(C12="july",7, IF(C12="august",8, IF(C12="september",9, IF(C12="october",10, IF(C12="november",11, IF(C12="december",12, )))))))))))) -> 4 | E12: 111.6 | F12: 110.9 | G12: 106.6 | H12: 105.7 | I12: 104.4 | J12: 108.9 | K12: 105.5 | L12: 105.3 | M12: 103.5 | N12: 103.3 | O12: 107.2 | P12: 109.6 | Q12: 107.7 | R12: 107.5 | S12: 108 | T12: 107 | U12: 107.9 | V12: 100.5 | W12: 106.5 | X12: 106.3 | Y12: 105.3 | Z12: 102.9 | AA12: 105 | AB12: 104.2 | AC12: 104.7 | AD12: 104.8 | AE12: 106.1
A13: Urban | B13: 2013 | C13: April | D13: =IF(C13="January",1, IF(C13="february",2, IF(C13="march",3, IF(C13="april",4, IF(C13="may",5, IF(C13="june",6, IF(C13="july",7, IF(C13="august",8, IF(C13="september",9, IF(C13="october",10, IF(C13="november",11, IF(C13="december",12, )))))))))))) -> 4 | E13: 114.6 | F13: 113.4 | G13: 106 | H13: 104.7 | I13: 102.1 | J13: 109.5 | K13: 109.7 | L13: 104.6 | M13: 102 | N13: 103.5 | O13: 108.2 | P13: 110.6 | Q13: 108.8 | R13: 108.5 | S13: 107.9 | T13: 106.4 | U13: 107.7 | V13: 100.5 | W13: 106.4 | X13: 106.5 | Y13: 105.7 | Z13: 103.2 | AA13: 105.2 | AB13: 104 | AC13: 105 | AD13: 105.1 | AE13: 105.7
A14: Rural | B14: 2013 | C14: May | D14: =IF(C14="January",1, IF(C14="february",2, IF(C14="march",3, IF(C14="april",4, IF(C14="may",5, IF(C14="june",6, IF(C14="july",7, IF(C14="august",8, IF(C14="september",9, IF(C14="october",10, IF(C14="november",11, IF(C14="december",12, )))))))))))) -> 5 | E14: 110.9 | F14: 109.8 | G14: 105.9 | H14: 107.5 | I14: 105.3 | J14: 108.1 | K14: 107.3 | L14: 106.1 | M14: 103.7 | N14: 104 | O14: 107.4 | P14: 109.9 | Q14: 108.1 | R14: 108.1 | S14: 108.8 | T14: 107.9 | U14: 108.6 | V14: ='Missing values'!V136 -> 100.5 | W14: 107.5 | X14: 106.8 | Y14: 105.7 | Z14: 102.1 | AA14: 105.5 | AB14: 105 | AC14: 104.1 | AD14: 104.8 | AE14: 107.2
A15: Rural+Urban | B15: 2013 | C15: May | D15: =IF(C15="January",1, IF(C15="february",2, IF(C15="march",3, IF(C15="april",4, IF(C15="may",5, IF(C15="june",6, IF(C15="july",7, IF(C15="august",8, IF(C15="september",9, IF(C15="october",10, IF(C15="november",11, IF(C15="december",12, )))))))))))) -> 5 | E15: 112.3 | F15: 111.3 | G15: 104.7 | H15: 106.8 | I15: 103.9 | J15: 109.3 | K15: 112.9 | L15: 105.8 | M15: 103.1 | N15: 104.3 | O15: 108.1 | P15: 110.5 | Q15: 109.2 | R15: 108.6 | S15: 108.7 | T15: 107.4 | U15: 108.5 | V15: 100.5 | W15: 107.4 | X15: 106.9 | Y15: 105.9 | Z15: 102.3 | AA15: 105.6 | AB15: 104.8 | AC15: 104 | AD15: 104.8 | AE15: 106.9
A16: Urban | B16: 2013 | C16: May | D16: =IF(C16="January",1, IF(C16="february",2, IF(C16="march",3, IF(C16="april",4, IF(C16="may",5, IF(C16="june",6, IF(C16="july",7, IF(C16="august",8, IF(C16="september",9, IF(C16="october",10, IF(C16="november",11, IF(C16="december",12, )))))))))))) -> 5 | E16: 115.4 | F16: 114.2 | G16: 102.7 | H16: 105.5 | I16: 101.5 | J16: 110.6 | K16: 123.7 | L16: 105.2 | M16: 101.9 | N16: 105 | O16: 109.1 | P16: 111.3 | Q16: 111.1 | R16: 109.8 | S16: 108.5 | T16: 106.7 | U16: 108.3 | V16: 100.5 | W16: 107.2 | X16: 107.1 | Y16: 106.2 | Z16: 102.6 | AA16: 105.7 | AB16: 104.6 | AC16: 103.9 | AD16: 104.9 | AE16: 106.6
A17: Rural | B17: 2013 | C17: June | D17: =IF(C17="January",1, IF(C17="february",2, IF(C17="march",3, IF(C17="april",4, IF(C17="may",5, IF(C17="june",6, IF(C17="july",7, IF(C17="august",8, IF(C17="september",9, IF(C17="october",10, IF(C17="november",11, IF(C17="december",12, )))))))))))) -> 6 | E17: 112.3 | F17: 112.1 | G17: 108.1 | H17: 108.3 | I17: 105.9 | J17: 109.2 | K17: 118 | L17: 106.8 | M17: 104.1 | N17: 105.4 | O17: 108.2 | P17: 111 | Q17: 110.6 | R17: 109 | S17: 109.7 | T17: 108.8 | U17: 109.5 | V17: ='Missing values'!V169 -> 106.6 | W17: 108.5 | X17: 107.5 | Y17: 106.3 | Z17: 102.5 | AA17: 106.5 | AB17: 105.6 | AC17: 105 | AD17: 105.5 | AE17: 108.9
A18: Rural+Urban | B18: 2013 | C18: June | D18: =IF(C18="January",1, IF(C18="february",2, IF(C18="march",3, IF(C18="april",4, IF(C18="may",5, IF(C18="june",6, IF(C18="july",7, IF(C18="august",8, IF(C18="september",9, IF(C18="october",10, IF(C18="november",11, IF(C18="december",12, )))))))))))) -> 6 | E18: 113.8 | F18: 114.9 | G18: 109.8 | H18: 107.9 | I18: 104.2 | J18: 110.7 | K18: 126.7 | L18: 106.3 | M18: 103.2 | N18: 105.7 | O18: 109 | P18: 111.6 | Q18: 112.2 | R18: 109.5 | S18: 109.5 | T18: 108.1 | U18: 109.3 | V18: 106.6 | W18: 108.3 | X18: 107.6 | Y18: 106.4 | Z18: 102.8 | AA18: 107.4 | AB18: 105.4 | AC18: 105.1 | AD18: 105.8 | AE18: 109.3
A19: Urban | B19: 2013 | C19: June | D19: =IF(C19="January",1, IF(C19="february",2, IF(C19="march",3, IF(C19="april",4, IF(C19="may",5, IF(C19="june",6, IF(C19="july",7, IF(C19="august",8, IF(C19="september",9, IF(C19="october",10, IF(C19="november",11, IF(C19="december",12, )))))))))))) -> 6 | E19: 117 | F19: 120.1 | G19: 112.5 | H19: 107.3 | I19: 101.3 | J19: 112.4 | K19: 143.6 | L19: 105.4 | M19: 101.4 | N19: 106.4 | O19: 110 | P19: 112.2 | Q19: 115 | R19: 110.9 | S19: 109.2 | T19: 107.2 | U19: 108.9 | V19: 106.6 | W19: 108 | X19: 107.7 | Y19: 106.5 | Z19: 103.3 | AA19: 108.1 | AB19: 105.2 | AC19: 105.2 | AD19: 106.1 | AE19: 109.7
A20: Rural | B20: 2013 | C20: July | D20: =IF(C20="January",1, IF(C20="february",2, IF(C20="march",3, IF(C20="april",4, IF(C20="may",5, IF(C20="june",6, IF(C20="july",7, IF(C20="august",8, IF(C20="september",9, IF(C20="october",10, IF(C20="november",11, IF(C20="december",12, )))))))))))) -> 7 | E20: 113.4 | F20: 114.9 | G20: 110.5 | H20: 109.3 | I20: 106.2 | J20: 110.3 | K20: 129.2 | L20: 107.1 | M20: 104.3 | N20: 106.4 | O20: 109.1 | P20: 112.1 | Q20: 113.1 | R20: 109.8 | S20: 110.5 | T20: 109.5 | U20: 110.3 | V20: ='Missing values'!V199 -> 107.7 | W20: 109.5 | X20: 108.3 | Y20: 106.9 | Z20: 102.5 | AA20: 107.8 | AB20: 106.4 | AC20: 106.8 | AD20: 106.5 | AE20: 110.7
A21: Rural+Urban | B21: 2013 | C21: July | D21: =IF(C21="January",1, IF(C21="february",2, IF(C21="march",3, IF(C21="april",4, IF(C21="may",5, IF(C21="june",6, IF(C21="july",7, IF(C21="august",8, IF(C21="september",9, IF(C21="october",10, IF(C21="november",11, IF(C21="december",12, )))))))))))) -> 7 | E21: 114.8 | F21: 116.4 | G21: 111.9 | H21: 108.9 | I21: 104.3 | J21: 111.7 | K21: 140 | L21: 106.4 | M21: 103.3 | N21: 106.8 | O21: 109.6 | P21: 112.6 | Q21: 114.7 | R21: 110.3 | S21: 110.2 | T21: 108.8 | U21: 110 | V21: 107.7 | W21: 109.2 | X21: 108.2 | Y21: 107 | Z21: 102.8 | AA21: 109.1 | AB21: 106.1 | AC21: 107.1 | AD21: 106.9 | AE21: 111
A22: Urban | B22: 2013 | C22: July | D22: =IF(C22="January",1, IF(C22="february",2, IF(C22="march",3, IF(C22="april",4, IF(C22="may",5, IF(C22="june",6, IF(C22="july",7, IF(C22="august",8, IF(C22="september",9, IF(C22="october",10, IF(C22="november",11, IF(C22="december",12, )))))))))))) -> 7 | E22: 117.8 | F22: 119.2 | G22: 114 | H22: 108.3 | I22: 101.1 | J22: 113.2 | K22: 160.9 | L22: 105.1 | M22: 101.3 | N22: 107.5 | O22: 110.4 | P22: 113.1 | Q22: 117.5 | R22: 111.7 | S22: 109.8 | T22: 107.8 | U22: 109.5 | V22: 107.7 | W22: 108.6 | X22: 108.1 | Y22: 107.1 | Z22: 103.2 | AA22: 110.1 | AB22: 105.9 | AC22: 107.3 | AD22: 107.3 | AE22: 111.4
A23: Rural | B23: 2013 | C23: August | D23: =IF(C23="January",1, IF(C23="february",2, IF(C23="march",3, IF(C23="april",4, IF(C23="may",5, IF(C23="june",6, IF(C23="july",7, IF(C23="august",8, IF(C23="september",9, IF(C23="october",10, IF(C23="november",11, IF(C23="december",12, )))))))))))) -> 8 | E23: 114.3 | F23: 115.4 | G23: 111.1 | H23: 110 | I23: 106.4 | J23: 110.8 | K23: 138.9 | L23: 107.4 | M23: 104.1 | N23: 106.9 | O23: 109.7 | P23: 112.6 | Q23: 114.9 | R23: 110.7 | S23: 111.3 | T23: 110.2 | U23: 111.1 | V23: ='Missing values'!V229 -> 108.9 | W23: 109.9 | X23: 108.7 | Y23: 107.5 | Z23: 105 | AA23: 108.7 | AB23: 106.8 | AC23: 107.8 | AD23: 107.5 | AE23: 112.1
A24: Rural+Urban | B24: 2013 | C24: August | D24: =IF(C24="January",1, IF(C24="february",2, IF(C24="march",3, IF(C24="april",4, IF(C24="may",5, IF(C24="june",6, IF(C24="july",7, IF(C24="august",8, IF(C24="september",9, IF(C24="october",10, IF(C24="november",11, IF(C24="december",12, )))))))))))) -> 8 | E24: 115.6 | F24: 117.2 | G24: 111.7 | H24: 109.6 | I24: 104.5 | J24: 109.8 | K24: 151.8 | L24: 106.5 | M24: 103.1 | N24: 107.4 | O24: 110.2 | P24: 113.4 | Q24: 116.6 | R24: 111.2 | S24: 111 | T24: 109.4 | U24: 110.7 | V24: 108.9 | W24: 109.7 | X24: 108.7 | Y24: 107.5 | Z24: 105.4 | AA24: 109.9 | AB24: 106.6 | AC24: 108 | AD24: 107.9 | AE24: 112.4
A25: Urban | B25: 2013 | C25: August | D25: =IF(C25="January",1, IF(C25="february",2, IF(C25="march",3, IF(C25="april",4, IF(C25="may",5, IF(C25="june",6, IF(C25="july",7, IF(C25="august",8, IF(C25="september",9, IF(C25="october",10, IF(C25="november",11, IF(C25="december",12, )))))))))))) -> 8 | E25: 118.3 | F25: 120.4 | G25: 112.7 | H25: 108.9 | I25: 101.1 | J25: 108.7 | K25: 177 | L25: 104.7 | M25: 101 | N25: 108.5 | O25: 110.9 | P25: 114.3 | Q25: 119.6 | R25: 112.4 | S25: 110.6 | T25: 108.3 | U25: 110.2 | V25: 108.9 | W25: 109.3 | X25: 108.7 | Y25: 107.6 | Z25: 106 | AA25: 110.8 | AB25: 106.5 | AC25: 108.1 | AD25: 108.3 | AE25: 112.7
A26: Rural | B26: 2013 | C26: September | D26: =IF(C26="January",1, IF(C26="february",2, IF(C26="march",3, IF(C26="april",4, IF(C26="may",5, IF(C26="june",6, IF(C26="july",7, IF(C26="august",8, IF(C26="september",9, IF(C26="october",10, IF(C26="november",11, IF(C26="december",12, )))))))))))) -> 9 | E26: 115.4 | F26: 115.7 | G26: 111.7 | H26: 111 | I26: 107.4 | J26: 110.9 | K26: 154 | L26: 108.1 | M26: 104.2 | N26: 107.9 | O26: 110.4 | P26: 114 | Q26: 117.8 | R26: 111.7 | S26: 112.7 | T26: 111.4 | U26: 112.5 | V26: ='Missing values'!V259 -> 109.7 | W26: 111.1 | X26: 109.6 | Y26: 108.3 | Z26: 106.7 | AA26: 109.8 | AB26: 107.7 | AC26: 109.3 | AD26: 108.7 | AE26: 114.2
A27: Rural+Urban | B27: 2013 | C27: September | D27: =IF(C27="January",1, IF(C27="february",2, IF(C27="march",3, IF(C27="april",4, IF(C27="may",5, IF(C27="june",6, IF(C27="july",7, IF(C27="august",8, IF(C27="september",9, IF(C27="october",10, IF(C27="november",11, IF(C27="december",12, )))))))))))) -> 9 | E27: 116.4 | F27: 116.9 | G27: 112.3 | H27: 110.5 | I27: 105.3 | J27: 107.3 | K27: 160.9 | L27: 107.1 | M27: 103.1 | N27: 108.3 | O27: 110.7 | P27: 114.6 | Q27: 118.3 | R27: 112 | S27: 112.2 | T27: 110.4 | U27: 111.9 | V27: 109.7 | W27: 110.5 | X27: 109.6 | Y27: 108.1 | Z27: 106.8 | AA27: 110.6 | AB27: 107.5 | AC27: 109.9 | AD27: 109 | AE27: 113.7
A28: Urban | B28: 2013 | C28: September | D28: =IF(C28="January",1, IF(C28="february",2, IF(C28="march",3, IF(C28="april",4, IF(C28="may",5, IF(C28="june",6, IF(C28="july",7, IF(C28="august",8, IF(C28="september",9, IF(C28="october",10, IF(C28="november",11, IF(C28="december",12, )))))))))))) -> 9 | E28: 118.6 | F28: 119.1 | G28: 113.2 | H28: 109.6 | I28: 101.7 | J28: 103.2 | K28: 174.3 | L28: 105.1 | M28: 100.8 | N28: 109.1 | O28: 111.1 | P28: 115.4 | Q28: 119.2 | R28: 112.9 | S28: 111.4 | T28: 109 | U28: 111.1 | V28: 109.7 | W28: 109.5 | X28: 109.6 | Y28: 107.9 | Z28: 106.9 | AA28: 111.2 | AB28: 107.4 | AC28: 110.4 | AD28: 109.4 | AE28: 113.2
A29: Rural | B29: 2013 | C29: October | D29: =IF(C29="January",1, IF(C29="february",2, IF(C29="march",3, IF(C29="april",4, IF(C29="may",5, IF(C29="june",6, IF(C29="july",7, IF(C29="august",8, IF(C29="september",9, IF(C29="october",10, IF(C29="november",11, IF(C29="december",12, )))))))))))) -> 10 | E29: 116.3 | F29: 115.4 | G29: 112.6 | H29: 111.7 | I29: 107.7 | J29: 113.2 | K29: 164.9 | L29: 108.3 | M29: 103.9 | N29: 108.2 | O29: 111.1 | P29: 114.9 | Q29: 119.8 | R29: 112.2 | S29: 113.6 | T29: 112.3 | U29: 113.4 | V29: ='Missing values'!V289 -> 110.5 | W29: 111.6 | X29: 110.4 | Y29: 108.9 | Z29: 107.5 | AA29: 110.2 | AB29: 108.3 | AC29: 109.3 | AD29: 109.1 | AE29: 115.5
A30: Rural+Urban | B30: 2013 | C30: October | D30: =IF(C30="January",1, IF(C30="february",2, IF(C30="march",3, IF(C30="april",4, IF(C30="may",5, IF(C30="june",6, IF(C30="july",7, IF(C30="august",8, IF(C30="september",9, IF(C30="october",10, IF(C30="november",11, IF(C30="december",12, )))))))))))) -> 10 | E30: 117.1 | F30: 116.3 | G30: 113.3 | H30: 111.2 | I30: 105.7 | J30: 109.9 | K30: 171.2 | L30: 107.3 | M30: 102.7 | N30: 108.7 | O30: 111.2 | P30: 115.4 | Q30: 120.2 | R30: 112.5 | S30: 113.2 | T30: 111.2 | U30: 112.8 | V30: 110.5 | W30: 110.9 | X30: 110.3 | Y30: 108.6 | Z30: 107.4 | AA30: 110.8 | AB30: 108.1 | AC30: 109.5 | AD30: 109.2 | AE30: 114.8
A31: Urban | B31: 2013 | C31: October | D31: =IF(C31="January",1, IF(C31="february",2, IF(C31="march",3, IF(C31="april",4, IF(C31="may",5, IF(C31="june",6, IF(C31="july",7, IF(C31="august",8, IF(C31="september",9, IF(C31="october",10, IF(C31="november",11, IF(C31="december",12, )))))))))))) -> 10 | E31: 118.9 | F31: 118.1 | G31: 114.5 | H31: 110.4 | I31: 102.3 | J31: 106.2 | K31: 183.5 | L31: 105.3 | M31: 100.2 | N31: 109.6 | O31: 111.4 | P31: 116 | Q31: 120.8 | R31: 113.5 | S31: 112.5 | T31: 109.7 | U31: 112 | V31: 110.5 | W31: 109.7 | X31: 110.2 | Y31: 108.2 | Z31: 107.3 | AA31: 111.3 | AB31: 108 | AC31: 109.7 | AD31: 109.4 | AE31: 114
A32: Rural | B32: 2013 | C32: November | D32: 11 | E32: 117.3 | F32: 114.9 | G32: 116.2 | H32: 112.8 | I32: 108.9 | J32: 116.6 | K32: 178.1 | L32: 109.1 | M32: 103.6 | N32: 109 | O32: 111.8 | P32: 116 | Q32: 122.5 | R32: 112.8 | S32: 114.6 | T32: 113.1 | U32: 114.4 | V32: ='Missing values'!V319 -> 111.1 | W32: 112.6 | X32: 111.3 | Y32: 109.7 | Z32: 108.2 | AA32: 111 | AB32: 108.7 | AC32: 109.6 | AD32: 109.8 | AE32: 117.4
A33: Rural+Urban | B33: 2013 | C33: November | D33: =IF(C33="January",1, IF(C33="february",2, IF(C33="march",3, IF(C33="april",4, IF(C33="may",5, IF(C33="june",6, IF(C33="july",7, IF(C33="august",8, IF(C33="september",9, IF(C33="october",10, IF(C33="november",11, IF(C33="december",12, )))))))))))) -> 11 | E33: 118.1 | F33: 115.4 | G33: 118.7 | H33: 112.5 | I33: 106.8 | J33: 113.5 | K33: 183.1 | L33: 108.2 | M33: 102.2 | N33: 109.4 | O33: 111.8 | P33: 116.5 | Q33: 122.6 | R33: 113.1 | S33: 114.2 | T33: 111.9 | U33: 113.8 | V33: 111.1 | W33: 111.6 | X33: 111.1 | Y33: 109.3 | Z33: 108.1 | AA33: 111.2 | AB33: 108.6 | AC33: 109.5 | AD33: 109.7 | AE33: 116.3
A34: Urban | B34: 2013 | C34: November | D34: =IF(C34="January",1, IF(C34="february",2, IF(C34="march",3, IF(C34="april",4, IF(C34="may",5, IF(C34="june",6, IF(C34="july",7, IF(C34="august",8, IF(C34="september",9, IF(C34="october",10, IF(C34="november",11, IF(C34="december",12, )))))))))))) -> 11 | E34: 119.8 | F34: 116.3 | G34: 122.6 | H34: 112 | I34: 103.2 | J34: 110 | K34: 192.8 | L34: 106.3 | M34: 99.5 | N34: 110.3 | O34: 111.8 | P34: 117.1 | Q34: 122.9 | R34: 114.1 | S34: 113.5 | T34: 110.3 | U34: 113 | V34: 111.1 | W34: 110 | X34: 110.9 | Y34: 108.6 | Z34: 107.9 | AA34: 111.3 | AB34: 108.5 | AC34: 109.5 | AD34: 109.6 | AE34: 115
A35: Rural | B35: 2013 | C35: December | D35: =IF(C35="January",1, IF(C35="february",2, IF(C35="march",3, IF(C35="april",4, IF(C35="may",5, IF(C35="june",6, IF(C35="july",7, IF(C35="august",8, IF(C35="september",9, IF(C35="october",10, IF(C35="november",11, IF(C35="december",12, )))))))))))) -> 12 | E35: 118.4 | F35: 115.9 | G35: 120.4 | H35: 113.8 | I35: 109.5 | J35: 115.5 | K35: 145.7 | L35: 109.5 | M35: 102.9 | N35: 109.8 | O35: 112.1 | P35: 116.8 | Q35: 118.7 | R35: 113.6 | S35: 115.8 | T35: 114 | U35: 115.5 | V35: ='Missing values'!V349 -> 110.7 | W35: 112.8 | X35: 112.1 | Y35: 110.1 | Z35: 108.1 | AA35: 111.6 | AB35: 109.2 | AC35: 109.9 | AD35: 110.1 | AE35: 115.5
A36: Rural+Urban | B36: 2013 | C36: December | D36: =IF(C36="January",1, IF(C36="february",2, IF(C36="march",3, IF(C36="april",4, IF(C36="may",5, IF(C36="june",6, IF(C36="july",7, IF(C36="august",8, IF(C36="september",9, IF(C36="october",10, IF(C36="november",11, IF(C36="december",12, )))))))))))) -> 12 | E36: 119.1 | F36: 116.7 | G36: 123.5 | H36: 113.4 | I36: 107.3 | J36: 113.3 | K36: 145.4 | L36: 108.7 | M36: 101.5 | N36: 110.5 | O36: 112.1 | P36: 117.4 | Q36: 118.4 | R36: 114 | S36: 115.2 | T36: 112.7 | U36: 114.8 | V36: 110.7 | W36: 111.9 | X36: 111.7 | Y36: 109.7 | Z36: 107.9 | AA36: 111.5 | AB36: 109 | AC36: 109.8 | AD36: 110 | AE36: 114.5
A37: Urban | B37: 2013 | C37: December | D37: =IF(C37="January",1, IF(C37="february",2, IF(C37="march",3, IF(C37="april",4, IF(C37="may",5, IF(C37="june",6, IF(C37="july",7, IF(C37="august",8, IF(C37="september",9, IF(C37="october",10, IF(C37="november",11, IF(C37="december",12, )))))))))))) -> 12 | E37: 120.5 | F37: 118.1 | G37: 128.5 | H37: 112.8 | I37: 103.4 | J37: 110.7 | K37: 144.8 | L37: 107.1 | M37: 98.6 | N37: 111.9 | O37: 112.1 | P37: 118.1 | Q37: 117.8 | R37: 115 | S37: 114.2 | T37: 110.9 | U37: 113.7 | V37: 110.7 | W37: 110.4 | X37: 111.3 | Y37: 109 | Z37: 107.7 | AA37: 111.4 | AB37: 108.9 | AC37: 109.7 | AD37: 109.8 | AE37: 113.3
A38: Rural | B38: 2014 | C38: January | D38: =IF(C38="January",1, IF(C38="february",2, IF(C38="march",3, IF(C38="april",4, IF(C38="may",5, IF(C38="june",6, IF(C38="july",7, IF(C38="august",8, IF(C38="september",9, IF(C38="october",10, IF(C38="november",11, IF(C38="december",12, )))))))))))) -> 1 | E38: 118.9 | F38: 117.1 | G38: 120.5 | H38: 114.4 | I38: 109 | J38: 115.5 | K38: 123.9 | L38: 109.6 | M38: 101.8 | N38: 110.2 | O38: 112.4 | P38: 117.3 | Q38: 116 | R38: 114 | S38: 116.5 | T38: 114.5 | U38: 116.2 | V38: ='Missing values'!V10 -> 111.6 | W38: 113 | X38: 112.6 | Y38: 110.6 | Z38: 108.3 | AA38: 111.8 | AB38: 109.6 | AC38: 110.5 | AD38: 110.6 | AE38: 114.2
A39: Rural+Urban | B39: 2014 | C39: January | D39: =IF(C39="January",1, IF(C39="february",2, IF(C39="march",3, IF(C39="april",4, IF(C39="may",5, IF(C39="june",6, IF(C39="july",7, IF(C39="august",8, IF(C39="september",9, IF(C39="october",10, IF(C39="november",11, IF(C39="december",12, )))))))))))) -> 1 | E39: 119.6 | F39: 118.8 | G39: 124.1 | H39: 114.1 | I39: 106.8 | J39: 113.9 | K39: 122.2 | L39: 108.9 | M39: 100.2 | N39: 111 | O39: 112.3 | P39: 118.1 | Q39: 115.8 | R39: 114.5 | S39: 115.8 | T39: 113.2 | U39: 115.4 | V39: 111.6 | W39: 112.2 | X39: 112.3 | Y39: 110.3 | Z39: 108.2 | AA39: 111.6 | AB39: 109.7 | AC39: 110.7 | AD39: 110.6 | AE39: 113.6
A40: Urban | B40: 2014 | C40: January | D40: =IF(C40="January",1, IF(C40="february",2, IF(C40="march",3, IF(C40="april",4, IF(C40="may",5, IF(C40="june",6, IF(C40="july",7, IF(C40="august",8, IF(C40="september",9, IF(C40="october",10, IF(C40="november",11, IF(C40="december",12, )))))))))))) -> 1 | E40: 121.2 | F40: 122 | G40: 129.9 | H40: 113.6 | I40: 102.9 | J40: 112.1 | K40: 118.9 | L40: 107.5 | M40: 96.9 | N40: 112.7 | O40: 112.1 | P40: 119 | Q40: 115.5 | R40: 115.7 | S40: 114.8 | T40: 111.3 | U40: 114.3 | V40: 111.6 | W40: 111 | X40: 111.9 | Y40: 109.7 | Z40: 108 | AA40: 111.5 | AB40: 109.8 | AC40: 110.8 | AD40: 110.5 | AE40: 112.9
...

Sheet Missing values
A1: Sector | B1: Year | C1: Month | D1: Month no. | E1: Cereals and products | F1: Meat and fish | G1: Egg | H1: Milk and products | I1: Oils and fats | J1: Fruits | K1: Vegetables | L1: Pulses and products | M1: Sugar and Confectionery | N1: Spices | O1: Nonalcoholic beverages | P1: Prepared meals, scks, sweets etc. | Q1: Food and beverages | R1: Pan, tobacco and intoxicants | S1: Clothing | T1: Footwear | U1: Clothing and footwear | V1: Housing | W1: Fuel and light | X1: Household goods and services | Y1: Health | Z1: Transport and communication | AA1: Recreation and amusement | AB1: Education | AC1: Persol care and effects | AD1: Miscellaneous | AE1: General index
A2: =COUNTBLANK('All_India_Index_Upto_April23 (1'!A2:A373) -> 0 | B2: =COUNTBLANK('All_India_Index_Upto_April23 (1'!B2:B373) -> 0 | C2: =COUNTBLANK('All_India_Index_Upto_April23 (1'!C2:C373) -> 0 | D2: =COUNTBLANK('All_India_Index_Upto_April23 (1'!D2:D373) -> 0 | E2: =COUNTBLANK('All_India_Index_Upto_April23 (1'!E2:E373) -> 3 | F2: =COUNTBLANK('All_India_Index_Upto_April23 (1'!F2:F373) -> 6 | G2: =COUNTBLANK('All_India_Index_Upto_April23 (1'!G2:G373) -> 3 | H2: =COUNTBLANK('All_India_Index_Upto_April23 (1'!H2:H373) -> 3 | ... Y2: =COUNTBLANK('All_India_Index_Upto_April23 (1'!Y2:Y373) -> 3 | Z2: =COUNTBLANK('All_India_Index_Upto_April23 (1'!AC2:AC373) -> 6 | AA2: =COUNTBLANK('All_India_Index_Upto_April23 (1'!AB2:AB373) -> 6 | AB2: =COUNTBLANK('All_India_Index_Upto_April23 (1'!AA2:AA373) -> 6 | AC2: =COUNTBLANK('All_India_Index_Upto_April23 (1'!Z2:Z373) -> 6 | AD2: =COUNTBLANK('All_India_Index_Upto_April23 (1'!AD2:AD373) -> 6 | AE2: =COUNTBLANK('All_India_Index_Upto_April23 (1'!AE2:AE373) -> 4
U4: Sector | V4: Housing
U5: Rural
U6: Rural+Urban | V6: 100.3
U7: Urban | V7: 100.3
R8: 111.6 | U8: Rural
R9: 117.3 | U9: Rural+Urban | V9: 111.6
U10: Urban | V10: 111.6
R11: 129.6 | U11: Rural
R12: 140.4 | U12: Rural+Urban | V12: 117.3
U13: Urban | V13: 117.3
R14: 153.9 | U14: Rural
R15: 157.7 | U15: Rural+Urban | V15: 123.4
U16: Urban | V16: 123.4
R17: 172.1 | U17: Rural
R18: 100.4 | U18: Rural+Urban | V18: 129.6
U19: Urban | V19: 129.6
R20: 118.1 | U20: Rural
R21: 124.4 | U21: Rural+Urban | V21: 140.4
U22: Urban | V22: 140.4
R23: 141.3 | U23: Rural
R24: 148.5 | U24: Rural+Urban | V24: 147.7
U25: Urban | V25: 147.7
R26: 159.8 | U26: Rural
R27: 165.5 | U27: Rural+Urban | V27: 153.9
U28: Urban | V28: 153.9
R29: 100.4 | U29: Rural
R30: 113.2 | U30: Rural+Urban | V30: 157.7
U31: Urban | V31: 157.7
R32: 124.9 | U32: Rural
R33: 131.1 | U33: Rural+Urban | V33: 164.5
U34: Urban | V34: 164.5
R35: 149 | U35: Rural
R36: 154.5 | U36: Rural+Urban | V36: 172.1
U37: Urban | V37: 172.1
R38: 165.3 | U38: Rural
R39: 173.5 | U39: Rural+Urban | V39: 100.4
U40: Urban | V40: 100.4
R41: 113.9 | U41: Rural
...

Sheet Basket
A1: Cereals and products | B1: Food and Beverages | D1: Sector | E1: Year | F1: Month | G1: Food and Beverages | H1: Pan, tobacco and intoxicants | I1: Clothing and footwear | J1: Household and Utilities | K1: Health,Education and Personal Care | L1: Miscellaneous | M1: General index
A2: Meat and fish | D2: Rural | E2: 2013 | F2: January | G2: =SUM('All_India_Index_Upto_April23 (1'!$E2:$Q2) -> 1371.7 | H2: =SUM('All_India_Index_Upto_April23 (1'!R2) -> 105.1 | I2: =SUM('All_India_Index_Upto_April23 (1'!$S2:$U2) -> 318.7 | J2: =SUM('All_India_Index_Upto_April23 (1'!$V2:$X2) -> 310.6 | K2: =SUM('All_India_Index_Upto_April23 (1'!$Y2:$AA2) -> 312.5 | L2: =SUM('All_India_Index_Upto_April23 (1'!$AB2:$AD2) -> 310.7 | M2: 105.1
A3: Egg | D3: Rural+Urban | E3: 2013 | F3: January | G3: =SUM('All_India_Index_Upto_April23 (1'!$E3:$Q3) -> 1373.3 | H3: =SUM('All_India_Index_Upto_April23 (1'!R3) -> 105.1 | I3: =SUM('All_India_Index_Upto_April23 (1'!$S3:$U3) -> 318 | J3: =SUM('All_India_Index_Upto_April23 (1'!$V3:$X3) -> 310.6 | K3: =SUM('All_India_Index_Upto_April23 (1'!$Y3:$AA3) -> 312.1 | L3: =SUM('All_India_Index_Upto_April23 (1'!$AB3:$AD3) -> 310.2 | M3: 104.6
A4: Milk and products | D4: Urban | E4: 2013 | F4: January | G4: =SUM('All_India_Index_Upto_April23 (1'!$E4:$Q4) -> 1376.4 | H4: =SUM('All_India_Index_Upto_April23 (1'!R4) -> 105.2 | I4: =SUM('All_India_Index_Upto_April23 (1'!$S4:$U4) -> 316.7 | J4: =SUM('All_India_Index_Upto_April23 (1'!$V4:$X4) -> 310.5 | K4: =SUM('All_India_Index_Upto_April23 (1'!$Y4:$AA4) -> 311.9 | L4: =SUM('All_India_Index_Upto_April23 (1'!$AB4:$AD4) -> 309.8 | M4: 104
A5: Oils and fats | D5: Rural | E5: 2013 | F5: February | G5: =SUM('All_India_Index_Upto_April23 (1'!$E5:$Q5) -> 1380.4 | H5: =SUM('All_India_Index_Upto_April23 (1'!R5) -> 105.6 | I5: =SUM('All_India_Index_Upto_April23 (1'!$S5:$U5) -> 320.4 | J5: =SUM('All_India_Index_Upto_April23 (1'!$V5:$X5) -> 311.8 | K5: =SUM('All_India_Index_Upto_April23 (1'!$Y5:$AA5) -> 313.1 | L5: =SUM('All_India_Index_Upto_April23 (1'!$AB5:$AD5) -> 312.3 | M5: 105.8
A6: Fruits | D6: Rural+Urban | E6: 2013 | F6: February | G6: =SUM('All_India_Index_Upto_April23 (1'!$E6:$Q6) -> 1384.2 | H6: =SUM('All_India_Index_Upto_April23 (1'!R6) -> 105.7 | I6: =SUM('All_India_Index_Upto_April23 (1'!$S6:$U6) -> 319.7 | J6: =SUM('All_India_Index_Upto_April23 (1'!$V6:$X6) -> 311.6 | K6: =SUM('All_India_Index_Upto_April23 (1'!$Y6:$AA6) -> 312.9 | L6: =SUM('All_India_Index_Upto_April23 (1'!$AB6:$AD6) -> 312.2 | M6: 105.3
A7: Vegetables | D7: Urban | E7: 2013 | F7: February | G7: =SUM('All_India_Index_Upto_April23 (1'!$E7:$Q7) -> 1390.6 | H7: =SUM('All_India_Index_Upto_April23 (1'!R7) -> 106 | I7: =SUM('All_India_Index_Upto_April23 (1'!$S7:$U7) -> 318.5 | J7: =SUM('All_India_Index_Upto_April23 (1'!$V7:$X7) -> 311.3 | K7: =SUM('All_India_Index_Upto_April23 (1'!$Y7:$AA7) -> 312.7 | L7: =SUM('All_India_Index_Upto_April23 (1'!$AB7:$AD7) -> 312 | M7: 104.7
A8: Pulses and products | D8: Rural | E8: 2013 | F8: March | G8: =SUM('All_India_Index_Upto_April23 (1'!$E8:$Q8) -> 1382.2 | H8: =SUM('All_India_Index_Upto_April23 (1'!R8) -> 106.5 | I8: =SUM('All_India_Index_Upto_April23 (1'!$S8:$U8) -> 321.9 | J8: =SUM('All_India_Index_Upto_April23 (1'!$V8:$X8) -> 312.1 | K8: =SUM('All_India_Index_Upto_April23 (1'!$Y8:$AA8) -> 313.3 | L8: =SUM('All_India_Index_Upto_April23 (1'!$AB8:$AD8) -> 313.2 | M8: 106
A9: Sugar and Confectionery | D9: Rural+Urban | E9: 2013 | F9: March | G9: =SUM('All_India_Index_Upto_April23 (1'!$E9:$Q9) -> 1384 | H9: =SUM('All_India_Index_Upto_April23 (1'!R9) -> 106.6 | I9: =SUM('All_India_Index_Upto_April23 (1'!$S9:$U9) -> 321.2 | J9: =SUM('All_India_Index_Upto_April23 (1'!$V9:$X9) -> 312.1 | K9: =SUM('All_India_Index_Upto_April23 (1'!$Y9:$AA9) -> 313.2 | L9: =SUM('All_India_Index_Upto_April23 (1'!$AB9:$AD9) -> 313.5 | M9: 105.5
A10: Spices | D10: Urban | E10: 2013 | F10: March | G10: =SUM('All_India_Index_Upto_April23 (1'!$E10:$Q10) -> 1386.8 | H10: =SUM('All_India_Index_Upto_April23 (1'!R10) -> 106.8 | I10: =SUM('All_India_Index_Upto_April23 (1'!$S10:$U10) -> 320.2 | J10: =SUM('All_India_Index_Upto_April23 (1'!$V10:$X10) -> 312.1 | K10: =SUM('All_India_Index_Upto_April23 (1'!$Y10:$AA10) -> 313.2 | L10: =SUM('All_India_Index_Upto_April23 (1'!$AB10:$AD10) -> 313.9 | M10: 105
A11: Nonalcoholic beverages | D11: Rural | E11: 2013 | F11: April | G11: =SUM('All_India_Index_Upto_April23 (1'!$E11:$Q11) -> 1385.8 | H11: =SUM('All_India_Index_Upto_April23 (1'!R11) -> 107.1 | I11: =SUM('All_India_Index_Upto_April23 (1'!$S11:$U11) -> 323.5 | J11: =SUM('All_India_Index_Upto_April23 (1'!$V11:$X11) -> 313.1 | K11: =SUM('All_India_Index_Upto_April23 (1'!$Y11:$AA11) -> 312.6 | L11: =SUM('All_India_Index_Upto_April23 (1'!$AB11:$AD11) -> 313.5 | M11: 106.4
A12: Prepared meals, scks, sweets etc. | D12: Rural+Urban | E12: 2013 | F12: April | G12: =SUM('All_India_Index_Upto_April23 (1'!$E12:$Q12) -> 1390.2 | H12: =SUM('All_India_Index_Upto_April23 (1'!R12) -> 107.5 | I12: =SUM('All_India_Index_Upto_April23 (1'!$S12:$U12) -> 322.9 | J12: =SUM('All_India_Index_Upto_April23 (1'!$V12:$X12) -> 313.3 | K12: =SUM('All_India_Index_Upto_April23 (1'!$Y12:$AA12) -> 313.2 | L12: =SUM('All_India_Index_Upto_April23 (1'!$AB12:$AD12) -> 313.7 | M12: 106.1
A13: Food and beverages | D13: Urban | E13: 2013 | F13: April | G13: =SUM('All_India_Index_Upto_April23 (1'!$E13:$Q13) -> 1397.7 | H13: =SUM('All_India_Index_Upto_April23 (1'!R13) -> 108.5 | I13: =SUM('All_India_Index_Upto_April23 (1'!$S13:$U13) -> 322 | J13: =SUM('All_India_Index_Upto_April23 (1'!$V13:$X13) -> 313.4 | K13: =SUM('All_India_Index_Upto_April23 (1'!$Y13:$AA13) -> 314.1 | L13: =SUM('All_India_Index_Upto_April23 (1'!$AB13:$AD13) -> 314.1 | M13: 105.7
A14: Pan, tobacco and intoxicants | B14: Pan, tobacco and intoxicants | D14: Rural | E14: 2013 | F14: May | G14: =SUM('All_India_Index_Upto_April23 (1'!$E14:$Q14) -> 1394 | H14: =SUM('All_India_Index_Upto_April23 (1'!R14) -> 108.1 | I14: =SUM('All_India_Index_Upto_April23 (1'!$S14:$U14) -> 325.3 | J14: =SUM('All_India_Index_Upto_April23 (1'!$V14:$X14) -> 314.8 | K14: =SUM('All_India_Index_Upto_April23 (1'!$Y14:$AA14) -> 313.3 | L14: =SUM('All_India_Index_Upto_April23 (1'!$AB14:$AD14) -> 313.9 | M14: 107.2
A15: Clothing | B15: Clothing and footwear | D15: Rural+Urban | E15: 2013 | F15: May | G15: =SUM('All_India_Index_Upto_April23 (1'!$E15:$Q15) -> 1402.2 | H15: =SUM('All_India_Index_Upto_April23 (1'!R15) -> 108.6 | I15: =SUM('All_India_Index_Upto_April23 (1'!$S15:$U15) -> 324.6 | J15: =SUM('All_India_Index_Upto_April23 (1'!$V15:$X15) -> 314.8 | K15: =SUM('All_India_Index_Upto_April23 (1'!$Y15:$AA15) -> 313.8 | L15: =SUM('All_India_Index_Upto_April23 (1'!$AB15:$AD15) -> 313.6 | M15: 106.9
A16: Footwear | D16: Urban | E16: 2013 | F16: May | G16: =SUM('All_India_Index_Upto_April23 (1'!$E16:$Q16) -> 1417.2 | H16: =SUM('All_India_Index_Upto_April23 (1'!R16) -> 109.8 | I16: =SUM('All_India_Index_Upto_April23 (1'!$S16:$U16) -> 323.5 | J16: =SUM('All_India_Index_Upto_April23 (1'!$V16:$X16) -> 314.8 | K16: =SUM('All_India_Index_Upto_April23 (1'!$Y16:$AA16) -> 314.5 | L16: =SUM('All_India_Index_Upto_April23 (1'!$AB16:$AD16) -> 313.4 | M16: 106.6
A17: Clothing and footwear | D17: Rural | E17: 2013 | F17: June | G17: =SUM('All_India_Index_Upto_April23 (1'!$E17:$Q17) -> 1420 | H17: =SUM('All_India_Index_Upto_April23 (1'!R17) -> 109 | I17: =SUM('All_India_Index_Upto_April23 (1'!$S17:$U17) -> 328 | J17: =SUM('All_India_Index_Upto_April23 (1'!$V17:$X17) -> 322.6 | K17: =SUM('All_India_Index_Upto_April23 (1'!$Y17:$AA17) -> 315.3 | L17: =SUM('All_India_Index_Upto_April23 (1'!$AB17:$AD17) -> 316.1 | M17: 108.9
A18: Housing | B18: Household and Utilities | D18: Rural+Urban | E18: 2013 | F18: June | G18: =SUM('All_India_Index_Upto_April23 (1'!$E18:$Q18) -> 1436 | H18: =SUM('All_India_Index_Upto_April23 (1'!R18) -> 109.5 | I18: =SUM('All_India_Index_Upto_April23 (1'!$S18:$U18) -> 326.9 | J18: =SUM('All_India_Index_Upto_April23 (1'!$V18:$X18) -> 322.5 | K18: =SUM('All_India_Index_Upto_April23 (1'!$Y18:$AA18) -> 316.6 | L18: =SUM('All_India_Index_Upto_April23 (1'!$AB18:$AD18) -> 316.3 | M18: 109.3
A19: Fuel and light | D19: Urban | E19: 2013 | F19: June | G19: =SUM('All_India_Index_Upto_April23 (1'!$E19:$Q19) -> 1464.6 | H19: =SUM('All_India_Index_Upto_April23 (1'!R19) -> 110.9 | I19: =SUM('All_India_Index_Upto_April23 (1'!$S19:$U19) -> 325.3 | J19: =SUM('All_India_Index_Upto_April23 (1'!$V19:$X19) -> 322.3 | K19: =SUM('All_India_Index_Upto_April23 (1'!$Y19:$AA19) -> 317.9 | L19: =SUM('All_India_Index_Upto_April23 (1'!$AB19:$AD19) -> 316.5 | M19: 109.7
A20: Household goods and services | D20: Rural | E20: 2013 | F20: July | G20: =SUM('All_India_Index_Upto_April23 (1'!$E20:$Q20) -> 1445.9 | H20: =SUM('All_India_Index_Upto_April23 (1'!R20) -> 109.8 | I20: =SUM('All_India_Index_Upto_April23 (1'!$S20:$U20) -> 330.3 | J20: =SUM('All_India_Index_Upto_April23 (1'!$V20:$X20) -> 325.5 | K20: =SUM('All_India_Index_Upto_April23 (1'!$Y20:$AA20) -> 317.2 | L20: =SUM('All_India_Index_Upto_April23 (1'!$AB20:$AD20) -> 319.7 | M20: 110.7
A21: Health | B21: Health,Education and Personal Care | D21: Rural+Urban | E21: 2013 | F21: July | G21: =SUM('All_India_Index_Upto_April23 (1'!$E21:$Q21) -> 1461.4 | H21: =SUM('All_India_Index_Upto_April23 (1'!R21) -> 110.3 | I21: =SUM('All_India_Index_Upto_April23 (1'!$S21:$U21) -> 329 | J21: =SUM('All_India_Index_Upto_April23 (1'!$V21:$X21) -> 325.1 | K21: =SUM('All_India_Index_Upto_April23 (1'!$Y21:$AA21) -> 318.9 | L21: =SUM('All_India_Index_Upto_April23 (1'!$AB21:$AD21) -> 320.1 | M21: 111
A22: Education | D22: Urban | E22: 2013 | F22: July | G22: =SUM('All_India_Index_Upto_April23 (1'!$E22:$Q22) -> 1489.4 | H22: =SUM('All_India_Index_Upto_April23 (1'!R22) -> 111.7 | I22: =SUM('All_India_Index_Upto_April23 (1'!$S22:$U22) -> 327.1 | J22: =SUM('All_India_Index_Upto_April23 (1'!$V22:$X22) -> 324.4 | K22: =SUM('All_India_Index_Upto_April23 (1'!$Y22:$AA22) -> 320.4 | L22: =SUM('All_India_Index_Upto_April23 (1'!$AB22:$AD22) -> 320.5 | M22: 111.4
A23: Persol care and effects | D23: Rural | E23: 2013 | F23: August | G23: =SUM('All_India_Index_Upto_April23 (1'!$E23:$Q23) -> 1462.5 | H23: =SUM('All_India_Index_Upto_April23 (1'!R23) -> 110.7 | I23: =SUM('All_India_Index_Upto_April23 (1'!$S23:$U23) -> 332.6 | J23: =SUM('All_India_Index_Upto_April23 (1'!$V23:$X23) -> 327.5 | K23: =SUM('All_India_Index_Upto_April23 (1'!$Y23:$AA23) -> 321.2 | L23: =SUM('All_India_Index_Upto_April23 (1'!$AB23:$AD23) -> 322.1 | M23: 112.1
A24: Transport and communication | B24: Miscellaneous | D24: Rural+Urban | E24: 2013 | F24: August | G24: =SUM('All_India_Index_Upto_April23 (1'!$E24:$Q24) -> 1477.4 | H24: =SUM('All_India_Index_Upto_April23 (1'!R24) -> 111.2 | I24: =SUM('All_India_Index_Upto_April23 (1'!$S24:$U24) -> 331.1 | J24: =SUM('All_India_Index_Upto_April23 (1'!$V24:$X24) -> 327.3 | K24: =SUM('All_India_Index_Upto_April23 (1'!$Y24:$AA24) -> 322.8 | L24: =SUM('All_India_Index_Upto_April23 (1'!$AB24:$AD24) -> 322.5 | M24: 112.4
A25: Recreation and amusement | D25: Urban | E25: 2013 | F25: August | G25: =SUM('All_India_Index_Upto_April23 (1'!$E25:$Q25) -> 1506.1 | H25: =SUM('All_India_Index_Upto_April23 (1'!R25) -> 112.4 | I25: =SUM('All_India_Index_Upto_April23 (1'!$S25:$U25) -> 329.1 | J25: =SUM('All_India_Index_Upto_April23 (1'!$V25:$X25) -> 326.9 | K25: =SUM('All_India_Index_Upto_April23 (1'!$Y25:$AA25) -> 324.4 | L25: =SUM('All_India_Index_Upto_April23 (1'!$AB25:$AD25) -> 322.9 | M25: 112.7
A26: Miscellaneous | D26: Rural | E26: 2013 | F26: September | G26: =SUM('All_India_Index_Upto_April23 (1'!$E26:$Q26) -> 1488.5 | H26: =SUM('All_India_Index_Upto_April23 (1'!R26) -> 111.7 | I26: =SUM('All_India_Index_Upto_April23 (1'!$S26:$U26) -> 336.6 | J26: =SUM('All_India_Index_Upto_April23 (1'!$V26:$X26) -> 330.4 | K26: =SUM('All_India_Index_Upto_April23 (1'!$Y26:$AA26) -> 324.8 | L26: =SUM('All_India_Index_Upto_April23 (1'!$AB26:$AD26) -> 325.7 | M26: 114.2
D27: Rural+Urban | E27: 2013 | F27: September | G27: =SUM('All_India_Index_Upto_April23 (1'!$E27:$Q27) -> 1491.7 | H27: =SUM('All_India_Index_Upto_April23 (1'!R27) -> 112 | I27: =SUM('All_India_Index_Upto_April23 (1'!$S27:$U27) -> 334.5 | J27: =SUM('All_India_Index_Upto_April23 (1'!$V27:$X27) -> 329.8 | K27: =SUM('All_India_Index_Upto_April23 (1'!$Y27:$AA27) -> 325.5 | L27: =SUM('All_India_Index_Upto_April23 (1'!$AB27:$AD27) -> 326.4 | M27: 113.7
D28: Urban | E28: 2013 | F28: September | G28: =SUM('All_India_Index_Upto_April23 (1'!$E28:$Q28) -> 1500.4 | H28: =SUM('All_India_Index_Upto_April23 (1'!R28) -> 112.9 | I28: =SUM('All_India_Index_Upto_April23 (1'!$S28:$U28) -> 331.5 | J28: =SUM('All_India_Index_Upto_April23 (1'!$V28:$X28) -> 328.8 | K28: =SUM('All_India_Index_Upto_April23 (1'!$Y28:$AA28) -> 326 | L28: =SUM('All_India_Index_Upto_April23 (1'!$AB28:$AD28) -> 327.2 | M28: 113.2
D29: Rural | E29: 2013 | F29: October | G29: =SUM('All_India_Index_Upto_April23 (1'!$E29:$Q29) -> 1508 | H29: =SUM('All_India_Index_Upto_April23 (1'!R29) -> 112.2 | I29: =SUM('All_India_Index_Upto_April23 (1'!$S29:$U29) -> 339.3 | J29: =SUM('All_India_Index_Upto_April23 (1'!$V29:$X29) -> 332.5 | K29: =SUM('All_India_Index_Upto_April23 (1'!$Y29:$AA29) -> 326.6 | L29: =SUM('All_India_Index_Upto_April23 (1'!$AB29:$AD29) -> 326.7 | M29: 115.5
D30: Rural+Urban | E30: 2013 | F30: October | G30: =SUM('All_India_Index_Upto_April23 (1'!$E30:$Q30) -> 1510.2 | H30: =SUM('All_India_Index_Upto_April23 (1'!R30) -> 112.5 | I30: =SUM('All_India_Index_Upto_April23 (1'!$S30:$U30) -> 337.2 | J30: =SUM('All_India_Index_Upto_April23 (1'!$V30:$X30) -> 331.7 | K30: =SUM('All_India_Index_Upto_April23 (1'!$Y30:$AA30) -> 326.8 | L30: =SUM('All_India_Index_Upto_April23 (1'!$AB30:$AD30) -> 326.8 | M30: 114.8
D31: Urban | E31: 2013 | F31: October | G31: =SUM('All_India_Index_Upto_April23 (1'!$E31:$Q31) -> 1517.2 | H31: =SUM('All_India_Index_Upto_April23 (1'!R31) -> 113.5 | I31: =SUM('All_India_Index_Upto_April23 (1'!$S31:$U31) -> 334.2 | J31: =SUM('All_India_Index_Upto_April23 (1'!$V31:$X31) -> 330.4 | K31: =SUM('All_India_Index_Upto_April23 (1'!$Y31:$AA31) -> 326.8 | L31: =SUM('All_India_Index_Upto_April23 (1'!$AB31:$AD31) -> 327.1 | M31: 114
D32: Rural | E32: 2013 | F32: November | G32: =SUM('All_India_Index_Upto_April23 (1'!$E32:$Q32) -> 1536.8 | H32: =SUM('All_India_Index_Upto_April23 (1'!R32) -> 112.8 | I32: =SUM('All_India_Index_Upto_April23 (1'!$S32:$U32) -> 342.1 | J32: =SUM('All_India_Index_Upto_April23 (1'!$V32:$X32) -> 335 | K32: =SUM('All_India_Index_Upto_April23 (1'!$Y32:$AA32) -> 328.9 | L32: =SUM('All_India_Index_Upto_April23 (1'!$AB32:$AD32) -> 328.1 | M32: 117.4
D33: Rural+Urban | E33: 2013 | F33: November | G33: =SUM('All_India_Index_Upto_April23 (1'!$E33:$Q33) -> 1538.8 | H33: =SUM('All_India_Index_Upto_April23 (1'!R33) -> 113.1 | I33: =SUM('All_India_Index_Upto_April23 (1'!$S33:$U33) -> 339.9 | J33: =SUM('All_India_Index_Upto_April23 (1'!$V33:$X33) -> 333.8 | K33: =SUM('All_India_Index_Upto_April23 (1'!$Y33:$AA33) -> 328.6 | L33: =SUM('All_India_Index_Upto_April23 (1'!$AB33:$AD33) -> 327.8 | M33: 116.3
D34: Urban | E34: 2013 | F34: November | G34: =SUM('All_India_Index_Upto_April23 (1'!$E34:$Q34) -> 1544.6 | H34: =SUM('All_India_Index_Upto_April23 (1'!R34) -> 114.1 | I34: =SUM('All_India_Index_Upto_April23 (1'!$S34:$U34) -> 336.8 | J34: =SUM('All_India_Index_Upto_April23 (1'!$V34:$X34) -> 332 | K34: =SUM('All_India_Index_Upto_April23 (1'!$Y34:$AA34) -> 327.8 | L34: =SUM('All_India_Index_Upto_April23 (1'!$AB34:$AD34) -> 327.6 | M34: 115
D35: Rural | E35: 2013 | F35: December | G35: =SUM('All_India_Index_Upto_April23 (1'!$E35:$Q35) -> 1509 | H35: =SUM('All_India_Index_Upto_April23 (1'!R35) -> 113.6 | I35: =SUM('All_India_Index_Upto_April23 (1'!$S35:$U35) -> 345.3 | J35: =SUM('All_India_Index_Upto_April23 (1'!$V35:$X35) -> 335.6 | K35: =SUM('All_India_Index_Upto_April23 (1'!$Y35:$AA35) -> 329.8 | L35: =SUM('All_India_Index_Upto_April23 (1'!$AB35:$AD35) -> 329.2 | M35: 115.5
D36: Rural+Urban | E36: 2013 | F36: December | G36: =SUM('All_India_Index_Upto_April23 (1'!$E36:$Q36) -> 1507.3 | H36: =SUM('All_India_Index_Upto_April23 (1'!R36) -> 114 | I36: =SUM('All_India_Index_Upto_April23 (1'!$S36:$U36) -> 342.7 | J36: =SUM('All_India_Index_Upto_April23 (1'!$V36:$X36) -> 334.3 | K36: =SUM('All_India_Index_Upto_April23 (1'!$Y36:$AA36) -> 329.1 | L36: =SUM('All_India_Index_Upto_April23 (1'!$AB36:$AD36) -> 328.8 | M36: 114.5
D37: Urban | E37: 2013 | F37: December | G37: =SUM('All_India_Index_Upto_April23 (1'!$E37:$Q37) -> 1504.4 | H37: =SUM('All_India_Index_Upto_April23 (1'!R37) -> 115 | I37: =SUM('All_India_Index_Upto_April23 (1'!$S37:$U37) -> 338.8 | J37: =SUM('All_India_Index_Upto_April23 (1'!$V37:$X37) -> 332.4 | K37: =SUM('All_India_Index_Upto_April23 (1'!$Y37:$AA37) -> 328.1 | L37: =SUM('All_India_Index_Upto_April23 (1'!$AB37:$AD37) -> 328.4 | M37: 113.3
D38: Rural | E38: 2014 | F38: January | G38: =SUM('All_India_Index_Upto_April23 (1'!$E38:$Q38) -> 1486.6 | H38: =SUM('All_India_Index_Upto_April23 (1'!R38) -> 114 | I38: =SUM('All_India_Index_Upto_April23 (1'!$S38:$U38) -> 347.2 | J38: =SUM('All_India_Index_Upto_April23 (1'!$V38:$X38) -> 337.2 | K38: =SUM('All_India_Index_Upto_April23 (1'!$Y38:$AA38) -> 330.7 | L38: =SUM('All_India_Index_Upto_April23 (1'!$AB38:$AD38) -> 330.7 | M38: 114.2
... D259: Urban | E259: 2020 | F259: March | G259: =SUM('All_India_Index_Upto_April23 (1'!$E259:$Q259) -> 1898.5 | H259: =SUM('All_India_Index_Upto_April23 (1'!R259) -> 173.3 | I259: =SUM('All_India_Index_Upto_April23 (1'!$S259:$U259) -> 427.1 | J259: =SUM('All_India_Index_Upto_April23 (1'!$V259:$X259) -> 436.7 | K259: =SUM('All_India_Index_Upto_April23 (1'!$Y259:$AA259) -> 442.8 | L259: =SUM('All_India_Index_Upto_April23 (1'!$AB259:$AD259) -> 401.2 | M259: 147.3
D260: Rural | E260: 2020 | F260: April | G260: =SUM('All_India_Index_Upto_April23 (1'!$E260:$Q260) -> 1614.8 | H260: =SUM('All_India_Index_Upto_April23 (1'!R260) -> 0 | I260: =SUM('All_India_Index_Upto_April23 (1'!$S260:$U260) -> 0 | J260: =SUM('All_India_Index_Upto_April23 (1'!$V260:$X260) -> 304 | K260: =SUM('All_India_Index_Upto_April23 (1'!$Y260:$AA260) -> 154.3 | L260: =SUM('All_India_Index_Upto_April23 (1'!$AB260:$AD260) -> 0
...

Sheet Problem 1
A1: Ques : Based on the latest month data, which broader category has the highest contribution towards CPI across all sectors?
A3: In the given dataset "MAY 2023 " is the latest month.
A5: RURAL | F5: URBAN | K5: RURAL + URBAN
A6: Categories | B6: Values | C6: Contribution % | F6: Categories | G6: Values | H6: Contribution % | K6: Categories | L6: Values | M6: Contribution %
A7: Food and Beverages | B7: 2290.7 | C7: =B7/$B$14 -> 0.4900522 | F7: Food and Beverages | G7: 2335.1 | H7: =G7/$G$14 -> 0.50315672 | K7: Food and Beverages | L7: 2306.9 | M7: =L7/$L$14 -> 0.49563854
A8: Pan, tobacco and intoxicants | B8: 199.9 | C8: =B8/$B$14 -> 0.042764847 | F8: Pan, tobacco and intoxicants | G8: 204.2 | H8: =G8/$G$14 -> 0.044000086 | K8: Pan, tobacco and intoxicants | L8: 201 | M8: =L8/$L$14 -> 0.043184943
A9: Clothing and footwear | B9: 569.9 | C9: =B9/$B$14 -> 0.12191939 | F9: Clothing and footwear | G9: 528.7 | H9: =G9/$G$14 -> 0.11392187 | K9: Clothing and footwear | L9: 553.2 | M9: =L9/$L$14 -> 0.11885528
A10: Household and Utilities | B10: 537.9 | C10: =B10/$B$14 -> 0.11507359 | F10: Household and Utilities | G10: 529.1 | H10: =G10/$G$14 -> 0.11400806 | K10: Household and Utilities | L10: 533.6 | M10: =L10/$L$14 -> 0.11464421
A11: Health,Education and Personal Care | B11: 553 | C11: =B11/$B$14 -> 0.11830395 | F11: Health,Education and Personal Care | G11: 542.6 | H11: =G11/$G$14 -> 0.11691698 | K11: Health,Education and Personal Care | L11: 548 | M11: =L11/$L$14 -> 0.11773805
A12: Miscellaneous | B12: 523 | C12: =B12/$B$14 -> 0.11188602 | F12: Miscellaneous | G12: 501.2 | H12: =G12/$G$14 -> 0.10799629 | K12: Miscellaneous | L12: 511.7 | M12: =L12/$L$14 -> 0.10993898
A14: TOTAL | B14: =SUM(B7:B12) -> 4674.4 | C14: =SUM(C7:C12) -> 1 | F14: TOTAL | G14: =SUM(G7:G12) -> 4640.9 | H14: =SUM(H7:H12) -> 1 | K14: TOTAL | L14: =SUM(L7:L12) -> 4654.4 | M14: =SUM(M7:M12) -> 1
A33: Food and Beverages contributes the highest in CPI calculation across all the sectors.

Sheet Problem 2
A1: Ques : Analyze the year-on-year CPI trend from 2017 and identify the year with the highest inflation and also find the reason .
A3: Sector | B3: Year | C3: Month | D3: General index | E3: YOY % change
A4: Rural+Urban | B4: 2016 | C4: May | D4: 128.6
A5: Rural+Urban | B5: 2017 | C5: May | D5: 131.4 | E5: =(D5-D4)/D4 -> 0.021772939
A6: Rural+Urban | B6: 2018 | C6: May | D6: 137.8 | E6: =(D6-D5)/D5 -> 0.04870624
A7: Rural+Urban | B7: 2019 | C7: May | D7: 142 | E7: =(D7-D6)/D6 -> 0.030478955
A8: Rural+Urban | B8: 2020 | C8: May | D8: 151.01667 | E8: =(D8-D7)/D7 -> 0.063497653
A9: Rural+Urban | B9: 2021 | C9: May | D9: 160.4 | E9: =(D9-D8)/D8 -> 0.062134422
A10: Rural+Urban | B10: 2022 | C10: May | D10: 171.7 | E10: =(D10-D9)/D9 -> 0.070448878
A11: Rural+Urban | B11: 2023 | C11: May | D11: 179.1 | E11: =(D11-D10)/D10 -> 0.043098427
A13: 2022 is the year with highest inflation rate.
A20: Why 2022 is the year with highest inflation rate?
A22: Sector | B22: Year | C22: Month | D22: Cereals and products | E22: Meat and fish | F22: Egg | G22: Milk and products | H22: Oils and fats | I22: Fruits | J22: Vegetables | K22: Pulses and products | L22: Sugar and Confectionery | M22: Spices | N22: Nonalcoholic beverages | O22: Prepared meals, scks, sweets etc. | P22: Food and beverages | Q22: Pan, tobacco and intoxicants | R22: Clothing | S22: Footwear | T22: Clothing and footwear | U22: Housing | V22: Fuel and light | W22: Household goods and services | X22: Health | Y22: Persol care and effects | Z22: Education | AA22: Recreation and amusement | AB22: Transport and communication | AC22: Miscellaneous
A23: Rural+Urban | B23: 2022 | C23: January | D23: 149.5 | E23: 198.7 | F23: 178.8 | G23: 160.5 | H23: 184.7 | I23: 153.7 | J23: 174.3 | K23: 163.9 | L23: 120 | M23: 172.1 | N23: 164.3 | O23: 177.3 | P23: 166.4 | Q23: 192.2 | R23: 169.9 | S23: 160.7 | T23: 168.5 | U23: 164.5 | V23: 164.2 | W23: 161.1 | X23: 171.4 | Y23: 163 | Z23: 164.7 | AA23: 161.2 | AB23: 156.5 | AC23: 162.7
A24: Rural+Urban | B24: 2022 | C24: February | D24: 150 | E24: 200.6 | F24: 175.8 | G24: 160.7 | H24: 184.9 | I24: 153.7 | J24: 169.7 | K24: 163.7 | L24: 118.9 | M24: 174.3 | N24: 164.7 | O24: 178 | P24: 166.2 | Q24: 192.8 | R24: 170.8 | S24: 162.4 | T24: 169.6 | U24: 165.5 | V24: 165.7 | W24: 161.8 | X24: 172.2 | Y24: 164.4 | Z24: 165.4 | AA24: 162.1 | AB24: 156.9 | AC24: 163.5
A25: Rural+Urban | B25: 2022 | C25: March | D25: 151.3 | E25: 210.7 | F25: 167.8 | G25: 162.2 | H25: 194.6 | I25: 157.6 | J25: 166.9 | K25: 163.9 | L25: 118.8 | M25: 177.4 | N25: 165.3 | O25: 179.3 | P25: 168.4 | Q25: 193.7 | R25: 172.1 | S25: 164.6 | T25: 171.1 | U25: 165.3 | V25: 167.2 | W25: 162.8 | X25: 173 | Y25: 167.2 | Z25: 166 | AA25: 163.3 | AB25: 157.9 | AC25: 164.6
A26: Rural+Urban | B26: 2022 | C26: April | D26: 152.9 | E26: 211.8 | F26: 164.5 | G26: 163.9 | H26: 199.5 | I26: 172.6 | J26: 166.2 | K26: 164.7 | L26: 119 | M26: 181.3 | N26: 166.2 | O26: 180.9 | P26: 170.8 | Q26: 193.9 | R26: 173.9 | S26: 166.5 | T26: 172.8 | U26: 167 | V26: 172.2 | W26: 164 | X26: 174 | Y26: 168.8 | Z26: 166.9 | AA26: 164.4 | AB26: 162.6 | AC26: 166.8
A27: Rural+Urban | B27: 2022 | C27: May | D27: 154.1 | E27: 217 | F27: 162.4 | G27: 164.9 | H27: 202.4 | I27: 171 | J27: 174.9 | K27: 164.7 | L27: 119.7 | M27: 184.9 | N27: 167.1 | O27: 182.5 | P27: 173.3 | Q27: 194.1 | R27: 175.6 | S27: 168.4 | T27: 174.6 | U27: 167.5 | V27: 174.6 | W27: 165.2 | X27: 174.8 | Y27: 168.4 | Z27: 167.9 | AA27: 165.1 | AB27: 163 | AC27: 167.5
A28: Rural+Urban | B28: 2022 | C28: June | D28: 155 | E28: 219.4 | F28: 170.8 | G28: 165.8 | H28: 200.9 | I28: 169.7 | J28: 182.3 | K28: 164.3 | L28: 119.9 | M28: 187.1 | N28: 167.9 | O28: 183.9 | P28: 174.9 | Q28: 194.3 | R28: 177.1 | S28: 169.9 | T28: 176 | U28: 166.8 | V28: 176 | W28: 166.4 | X28: 175.4 | Y28: 169.4 | Z28: 169 | AA28: 165.8 | AB28: 161.1 | AC28: 167.5
A29: Rural+Urban | B29: 2022 | C29: July | D29: 156.5 | E29: 213 | F29: 175.2 | G29: 166.6 | H29: 195.8 | I29: 174.2 | J29: 182.1 | K29: 164.3 | L29: 120 | M29: 190 | N29: 168.4 | O29: 185.2 | P29: 175 | Q29: 194.6 | R29: 178.3 | S29: 171.3 | T29: 177.3 | U29: 167.8 | V29: 179.6 | W29: 167.4 | X29: 176.1 | Y29: 169.7 | Z29: 171.4 | AA29: 166.3 | AB29: 161.6 | AC29: 168.4
A30: Rural+Urban | B30: 2022 | C30: August | D30: 160.3 | E30: 206.5 | F30: 169.2 | G30: 168.1 | H30: 192.4 | I30: 172.9 | J30: 186.7 | K30: 167.2 | L30: 120.9 | M30: 193.6 | N30: 168.8 | O30: 186.3 | P30: 176.3 | Q30: 195 | R30: 179.5 | S30: 172.7 | T30: 178.5 | U30: 169 | V30: 178.8 | W30: 168.5 | X30: 176.8 | Y30: 171.2 | Z30: 172.3 | AA30: 166.9 | AB30: 161.9 | AC30: 169.1
A31: Rural+Urban | B31: 2022 | C31: September | D31: 163.5 | E31: 209.2 | F31: 169.7 | G31: 169.7 | H31: 188.7 | I31: 165.7 | J31: 191.8 | K31: 169.1 | L31: 121.6 | M31: 197.3 | N31: 169.4 | O31: 187.4 | P31: 177.8 | Q31: 195.9 | R31: 180.9 | S31: 174.3 | T31: 179.9 | U31: 169.5 | V31: 179.5 | W31: 169.5 | X31: 177.8 | Y31: 170.9 | Z31: 173.1 | AA31: 167.6 | AB31: 162.3 | AC31: 169.7
A32: Rural+Urban | B32: 2022 | C32: October | D32: 165.2 | E32: 210.9 | F32: 170.9 | G32: 170.9 | H32: 186.5 | I32: 163.8 | J32: 199.7 | K32: 169.8 | L32: 121.9 | M32: 199.9 | N32: 169.9 | O32: 188.3 | P32: 179.6 | Q32: 196.3 | R32: 181.9 | S32: 175.3 | T32: 181 | U32: 171.2 | V32: 180.5 | W32: 170.4 | X32: 178.7 | Y32: 172.1 | Z32: 173.4 | AA32: 168.2 | AB32: 162.9 | AC32: 170.5
A33: Rural+Urban | B33: 2022 | C33: November | D33: 167.4 | E33: 209.4 | F33: 181.4 | G33: 172.3 | H33: 188.9 | I33: 160.7 | J33: 183.1 | K33: 170.5 | L33: 122.1 | M33: 202.8 | N33: 170.4 | O33: 189.5 | P33: 178.3 | Q33: 196.9 | R33: 183.1 | S33: 176.2 | T33: 182.1 | U33: 171.8 | V33: 181.3 | W33: 171.4 | X33: 179.8 | Y33: 173.6 | Z33: 173.7 | AA33: 168.5 | AB33: 163 | AC33: 171.1
A34: Rural+Urban | B34: 2022 | C34: December | D34: 169.2 | E34: 209 | F34: 190.2 | G34: 173.6 | H34: 188.5 | I34: 158 | J34: 159.9 | K34: 170.8 | L34: 121.8 | M34: 205.2 | N34: 171 | O34: 190.3 | P34: 175.9 | Q34: 197.3 | R34: 184 | S34: 177 | T34: 183 | U34: 170.7 | V34: 182 | W34: 172.1 | X34: 181.1 | Y34: 175.8 | Z34: 174.1 | AA34: 168.9 | AB34: 163.4 | AC34: 172
C36: INFLATION % | D36: =(D34-D23)/D23 -> 0.13177258 | E36: =(E34-E23)/E23 -> 0.05183694 | F36: =(F34-F23)/F23 -> 0.063758389 | G36: =(G34-G23)/G23 -> 0.081619938 | H36: =(H34-H23)/H23 -> 0.020573904 | I36: =(I34-I23)/I23 -> 0.027976578 | J36: =(J34-J23)/J23 -> -0.082616179 | K36: =(K34-K23)/K23 -> 0.042098841 | ... AC36: =(AC34-AC23)/AC23 -> 0.057160418
A39: Prices of Cereals and products, Spices and Fuel and light increased in year 2022 which is the reason of high inflation rate in the year 2022.

Sheet Problem 3 data
A1: Ques : Analyze food category price trends from June 2022 to May 2023 and identify the month with the highest food inflation.
A3: Sector | B3: Year | C3: Month | D3: Month no. | E3: Food and Beverages | I3: Sectors | J3: Year | K3: Month | L3: Month no. | M3: Cereals and products | N3: Meat and fish | O3: Egg | P3: Milk and products | Q3: Oils and fats | R3: Fruits | S3: Vegetables | T3: Pulses and products | U3: Sugar and Confectionery | V3: Spices | W3: Nonalcoholic beverages | X3: Prepared meals, scks, sweets etc. | Y3: Food and beverages
A4: Rural | B4: 2022 | C4: May | D4: 5 | E4: 2226.8 | I4: Rural | J4: 2022 | K4: May | L4: =IF(K4="January",1, IF(K4="february",2, IF(K4="march",3, IF(K4="april",4, IF(K4="may",5, IF(K4="june",6, IF(K4="july",7, IF(K4="august",8, IF(K4="september",9, IF(K4="october",10, IF(K4="november",11, IF(K4="december",12, )))))))))))) -> 5 | M4: 152.9 | N4: 214.7 | O4: 161.4 | P4: 164.6 | Q4: 209.9 | R4: 168 | S4: 160.4 | T4: 165 | U4: 118.9 | V4: 186.6 | W4: 173.2 | X4: 180.4 | Y4: 170.8
A5: Rural+Urban | B5: 2022 | C5: May | D5: 5 | E5: 2238.9 | I5: Rural+Urban | J5: 2022 | K5: May | L5: =IF(K5="January",1, IF(K5="february",2, IF(K5="march",3, IF(K5="april",4, IF(K5="may",5, IF(K5="june",6, IF(K5="july",7, IF(K5="august",8, IF(K5="september",9, IF(K5="october",10, IF(K5="november",11, IF(K5="december",12, )))))))))))) -> 5 | M5: 154.1 | N5: 217 | O5: 162.4 | P5: 164.9 | Q5: 202.4 | R5: 171 | S5: 174.9 | T5: 164.7 | U5: 119.7 | V5: 184.9 | W5: 167.1 | X5: 182.5 | Y5: 173.3
A6: Urban | B6: 2022 | C6: May | D6: 5 | E6: 2262.2 | I6: Urban | J6: 2022 | K6: May | L6: =IF(K6="January",1, IF(K6="february",2, IF(K6="march",3, IF(K6="april",4, IF(K6="may",5, IF(K6="june",6, IF(K6="july",7, IF(K6="august",8, IF(K6="september",9, IF(K6="october",10, IF(K6="november",11, IF(K6="december",12, )))))))))))) -> 5 | M6: 156.7 | N6: 221.2 | O6: 164.1 | P6: 165.4 | Q6: 189.5 | R6: 174.5 | S6: 203.2 | T6: 164.1 | U6: 121.2 | V6: 181.4 | W6: 158.5 | X6: 184.9 | Y6: 177.5
A7: Rural | B7: 2022 | C7: June | D7: 6 | E7: 2248.3 | I7: Rural | J7: 2022 | K7: June | L7: 6 | M7: 153.8 | N7: 217.2 | O7: 169.6 | P7: 165.4 | Q7: 208.1 | R7: 165.8 | S7: 167.3 | T7: 164.6 | U7: 119.1 | V7: 188.9 | W7: 174.2 | X7: 181.9 | Y7: 172.4
A8: Rural+Urban | B8: 2022 | C8: June | D8: 6 | E8: 2261.9 | I8: Rural+Urban | J8: 2022 | K8: June | L8: 6 | M8: 155 | N8: 219.4 | O8: 170.8 | P8: 165.8 | Q8: 200.9 | R8: 169.7 | S8: 182.3 | T8: 164.3 | U8: 119.9 | V8: 187.1 | W8: 167.9 | X8: 183.9 | Y8: 174.9
A9: Urban | B9: 2022 | C9: June | D9: 6 | E9: 2287.5 | I9: Urban | J9: 2022 | K9: June | L9: 6 | M9: 157.5 | N9: 223.4 | O9: 172.8 | P9: 166.4 | Q9: 188.6 | R9: 174.1 | S9: 211.5 | T9: 163.6 | U9: 121.4 | V9: 183.5 | W9: 159.1 | X9: 186.3 | Y9: 179.3
A10: Rural | B10: 2022 | C10: July | D10: 7 | E10: 2252.5 | I10: Rural | J10: 2022 | K10: July | L10: 7 | M10: 155.2 | N10: 210.8 | O10: 174.3 | P10: 166.3 | Q10: 202.2 | R10: 169.6 | S10: 168.6 | T10: 164.4 | U10: 119.2 | V10: 191.8 | W10: 174.5 | X10: 183.1 | Y10: 172.5
